<?xml version="1.0" ?>
<robot name="turtlebot3_waffle" xmlns:xacro="http://ros.org/wiki/xacro">
  <xacro:include filename="$(find turtlebot3_description)/urdf/common_properties.xacro"/>
  <xacro:include filename="$(find turtlebot3_description)/urdf/turtlebot3_waffle.gazebo.xacro"/>

  <link name="base_footprint"/>

  <joint name="base_joint" type="fixed">
    <parent link="base_footprint"/>
    <child link="base_link"/>
    <origin xyz="0 0 0" rpy="0 0 0"/>
  </joint>

  <link name="base_link">
    <visual>
      <origin xyz="0 0 0" rpy="0 0 0"/>
      <geometry>
        <mesh filename="package://turtlebot3_description/meshes/bases/base_link.STL" />
      </geometry>
      <material name="light_black"/>
    </visual>

    <collision>
      <origin xyz="0 0 0" rpy="0 0 0"/>
      <geometry>
        <mesh filename="package://turtlebot3_description/meshes/bases/base_link.STL" />
      </geometry>
    </collision>

    <inertial>
      <origin xyz="-1.61402176119143E-05 0.211585363756747 1.99118160999409E-08" rpy="0 0 0"/>
      <mass value="4.97825119597728"/>
      <inertia
        ixx="0.0254562268649868"
        ixy="2.61811741763744E-08"
        ixz="-1.52281155067974E-10"
        iyy="0.0769425840258945"
        iyz="-1.42371428386064E-09"
        izz="0.0715575020127173" />
    </inertial>
  </link>

  <joint name="wheel_left_joint" type="continuous">
    <parent link="base_link"/>
    <child link="wheel_left_link"/>
    <origin xyz="0 0.2075 0.075638" rpy="-1.5708 0 0"/>
    <axis xyz="0 0 1"/>
    <dynamics friction="0.01"/>
  </joint>

  <link name="wheel_left_link">
    <visual>
      <origin xyz="0 0 0" rpy="0 0 0"/>
      <geometry>
        <mesh filename="package://turtlebot3_description/meshes/wheels/wheel_left_link.STL"/>
      </geometry>
      <material name="red"/>
    </visual>

    <collision>
      <origin xyz="0 0 0" rpy="0 0 0"/>
      <geometry>
        <mesh filename="package://turtlebot3_description/meshes/wheels/wheel_left_link.STL"/>
      </geometry>
      <surface>
       <friction>
        <ode>
         <mu>0.7</mu>
         <mu2>0.7</mu2>
        </ode>
       </friction> 
      </surface>
    </collision>

    <inertial>
      <origin xyz="1.8744E-15 -7.9797E-15 -0.0275" />
      <mass value="0.69027" />
       <inertia
        ixx="0.0012793"
        ixy="4.9184E-37"
        ixz="3.4973E-20"
        iyy="0.0012793"
        iyz="-2.2668E-36"
        izz="0.0022925" />
      </inertial>
  </link>

  <joint name="wheel_right_joint" type="continuous">
    <parent link="base_link"/>
    <child link="wheel_right_link"/>
    <origin xyz="0 -0.1525 0.075638" rpy="-1.5708 0 0"/>
    <axis xyz="0 0 1"/>
    <dynamics friction="0.01"/>
  </joint>

  <link name="wheel_right_link">
    <visual>
      <origin xyz="0 0 0" rpy="0 0 0"/>
      <geometry>
        <mesh filename="package://turtlebot3_description/meshes/wheels/wheel_left_link.STL"/>
      </geometry>
      <material name="red"/>
    </visual>

    <collision>
      <origin xyz="0 0 0" rpy="0 0 0"/>
      <geometry>
        <mesh filename="package://turtlebot3_description/meshes/wheels/wheel_left_link.STL"/>
      </geometry>
      <surface>
       <friction>
        <ode>
         <mu>0.7</mu>
         <mu2>0.7</mu2>
        </ode>
       </friction> 
      </surface>
    </collision>

    <inertial>
      <origin xyz="6.5181E-15 4.3313E-14 0.0275" />
      <mass value="0.69027" />
      <inertia
        ixx="0.0012793"
        ixy="-4.8678E-37"
        ixz="4.6267E-20"
        iyy="0.0012793"
        iyz="-2.2668E-36"
        izz="0.0022925" />
      </inertial>
  </link>

  <joint name="imu_joint" type="fixed">
    <parent link="base_link"/>
    <child link="imu_link"/>
    <origin xyz="0 0 0.10" rpy="0 0 0"/>
  </joint>

  <link name="imu_link"/>
  
    <joint name="scan_joint" type="fixed">
    <parent link="base_link"/>
    <child link="base_scan"/>
    <origin xyz="0 0 0.438" rpy="0 0 0"/>
  </joint>

  <link name="base_scan">
    <visual>
      <origin xyz="0 0 0" rpy="0 0 0"/>
      <geometry>
        <mesh filename="package://turtlebot3_description/meshes/sensors/lds.stl" scale="0.001 0.001 0.001"/>
      </geometry>
      <material name="dark"/>
    </visual>

    <collision>
      <origin xyz="0.015 0 -0.0065" rpy="0 0 0"/>
      <geometry>
        <cylinder length="0.0315" radius="0.055"/>
      </geometry>
    </collision>

    <inertial>
      <mass value="0.114" />
      <origin xyz="0 0 0" />
      <inertia ixx="0.001" ixy="0.0" ixz="0.0"
               iyy="0.001" iyz="0.0"
               izz="0.001" />
    </inertial>
  </link>

   <joint name="caster1_joint" type="fixed">
    <parent link="base_link"/>
    <child link="caster1_link"/>
    <origin xyz="0.27449 0.20468 0.046466" rpy="1.5708 0 0"/>
    <axis xyz="0 0 0"/>
  </joint>


  <link name="caster1_link">
      <visual>
      <origin xyz="0 0 0" rpy="0 0 0"/>
      <geometry>
        <mesh filename="package://turtlebot3_description/meshes/wheels/caster1_link.STL" />
      </geometry>
      <material name="white"/>
    </visual>
    
    <collision>
      <origin xyz="0 0 0" rpy="0 0 0"/>
      <geometry>
        <mesh filename="package://turtlebot3_description/meshes/wheels/caster1_link.STL" />
      </geometry>
    </collision>

    <inertial>
      <origin xyz="-0.010009 0.016251 0.01778" />
      <mass value="0.038755" />
      <inertia 
        ixx="2.3231E-05"
        ixy="9.1783E-06"
        ixz="2.2409E-21"
        iyy="1.6245E-05"
        iyz="-1.1984E-21"
        izz="2.7613E-05" />
    </inertial>
  </link> 
  
   <joint name="caster2_joint" type="fixed">
    <parent link="base_link"/>
    <child link="caster2_link"/>
    <origin xyz="0.27449 -0.16912 0.046466" rpy="1.5708 0 0"/>
    <axis xyz="0 0 0"/>
  </joint>

  <link name="caster2_link">
      <visual>
      <origin xyz="0 0 0" rpy="0 0 0"/>
      <geometry>
        <mesh filename="package://turtlebot3_description/meshes/wheels/caster2_link.STL" />
      </geometry>
      <material name="white"/>
    </visual>
    
    <collision>
      <origin xyz="0 0 0" rpy="0 0 0"/>
      <geometry>
        <mesh filename="package://turtlebot3_description/meshes/wheels/caster2_link.STL" />
      </geometry>
    </collision>

    <inertial>
      <origin xyz="-0.010009 0.016251 0.01778" />
      <mass value="0.038755" />
      <inertia 
        ixx="2.3231E-05"
        ixy="9.1783E-06"
        ixz="3.4536E-22"
        iyy="1.6245E-05"
        iyz="-6.0741E-23"
        izz="2.7613E-05" />
    </inertial>
  </link> 
  
     <joint name="caster3_joint" type="fixed">
    <parent link="base_link"/>
    <child link="caster3_link"/>
    <origin xyz="-0.22061 0.20468 0.046466" rpy="1.5708 0 0"/>
    <axis xyz="0 0 0"/>
  </joint>

  <link name="caster3_link">
      <visual>
      <origin xyz="0 0 0" rpy="0 0 0"/>
      <geometry>
        <mesh filename="package://turtlebot3_description/meshes/wheels/caster3_link.STL" />
      </geometry>
      <material name="white"/>
    </visual>
    
    <collision>
      <origin xyz="0 0 0" rpy="0 0 0"/>
      <geometry>
        <mesh filename="package://turtlebot3_description/meshes/wheels/caster3_link.STL" />
      </geometry>
    </collision>

    <inertial>
      <origin xyz="-0.010009 0.016251 0.01778" />
      <mass value="0.038755" />
      <inertia 
        ixx="2.3231E-05"
        ixy="9.1783E-06"
        ixz="-1.6302E-21"
        iyy="1.6245E-05"
        iyz="4.2278E-23"
        izz="2.7613E-05" />
    </inertial>
  </link> 
  
    <joint name="caster4_joint" type="fixed">
    <parent link="base_link"/>
    <child link="caster4_link"/>
    <origin xyz="-0.22061 -0.16912 0.046466" rpy="1.5708 0 0"/>
    <axis xyz="0 0 0"/>
  </joint>

  <link name="caster4_link">
      <visual>
      <origin xyz="0 0 0" rpy="0 0 0"/>
      <geometry>
        <mesh filename="package://turtlebot3_description/meshes/wheels/caster4_link.STL" />
      </geometry>
      <material name="white"/>
    </visual>
    
    <collision>
      <origin xyz="0 0 0" rpy="0 0 0"/>
      <geometry>
        <mesh filename="package://turtlebot3_description/meshes/wheels/caster4_link.STL" />
      </geometry>
    </collision>

    <inertial>
      <origin xyz="-0.010009 0.016251 0.01778" />
      <mass value="0.038755" />
      <inertia 
        ixx="2.3231E-05"
        ixy="9.1783E-06"
        ixz="-1.0983E-21"
        iyy="1.6245E-05"
        iyz="1.7878E-22"
        izz="2.7613E-05" />
    </inertial>
  </link> 
  
    <joint name="roda1_joint" type="fixed">
    <parent link="caster1_link"/>
    <child link="roda1_link"/>
    <origin xyz="0 -0.0035 0" rpy="0 0 0.057049"/>
    <axis xyz="0 0 0"/>
    <dynamics damping="0" friction="0"/>
  </joint>
  
  <link name="roda1_link">
      <visual>
      <origin xyz="0 0 0" rpy="0 0 0"/>
      <geometry>
        <mesh filename="package://turtlebot3_description/meshes/wheels/roda1_link.STL" />
      </geometry>
      <material name="orange"/>
    </visual>
    
    <collision>
      <origin xyz="0 0 0" rpy="0 0 0"/>
      <geometry>
        <mesh filename="package://turtlebot3_description/meshes/wheels/roda1_link.STL" />
      </geometry>
      <surface>
       <friction>
        <ode>
         <mu>0</mu>
         <mu2>0</mu2>
        </ode>
       </friction> 
      </surface>
    </collision>

    <inertial>
      <origin xyz="3.3307E-16 -2.0227E-15 0.017714" />
      <mass value="0.13541" />
      <inertia 
        ixx="7.4142E-05"
        ixy="-8.4703E-22"
        ixz="9.1514E-19"
        iyy="7.4142E-05"
        iyz="-6.5014E-18"
        izz="0.00013101" />
    </inertial>
  </link> 
  
    <joint name="roda2_joint" type="fixed">
    <parent link="caster2_link"/>
    <child link="roda2_link"/>
    <origin xyz="0 -0.0035 0" rpy="0 0 0.057049"/>
    <axis xyz="0 0 0"/>
    <dynamics damping="0" friction="0"/>
  </joint>
  
  <link name="roda2_link">
      <visual>
      <origin xyz="0 0 0" rpy="0 0 0"/>
      <geometry>
        <mesh filename="package://turtlebot3_description/meshes/wheels/roda2_link.STL" />
      </geometry>
      <material name="orange"/>
    </visual>
    
    <collision>
      <origin xyz="0 0 0" rpy="0 0 0"/>
      <geometry>
        <mesh filename="package://turtlebot3_description/meshes/wheels/roda2_link.STL" />
      </geometry>
      <surface>
       <friction>
        <ode>
         <mu>0</mu>
         <mu2>0</mu2>
        </ode>
       </friction> 
      </surface>
    </collision>

    <inertial>
      <origin xyz="2.7756E-16 -2.1233E-15 0.017714" />
      <mass value="0.13541" />
      <inertia 
        ixx="7.4142E-05"
        ixy="-8.4703E-22"
        ixz="9.0007E-19"
        iyy="7.4142E-05"
        iyz="-6.7956E-18"
        izz="0.00013101" />
    </inertial>
  </link> 
  
    <joint name="roda3_joint" type="fixed">
    <parent link="caster3_link"/>
    <child link="roda3_link"/>
    <origin xyz="0 -0.0035 0" rpy="0 0 0.057049"/>
    <axis xyz="0 0 0"/>
    <dynamics damping="0" friction="0"/>
  </joint>
  
  <link name="roda3_link">
      <visual>
      <origin xyz="0 0 0" rpy="0 0 0"/>
      <geometry>
        <mesh filename="package://turtlebot3_description/meshes/wheels/roda3_link.STL" />
      </geometry>
      <material name="orange"/>
    </visual>
    
    <collision>
      <origin xyz="0 0 0" rpy="0 0 0"/>
      <geometry>
        <mesh filename="package://turtlebot3_description/meshes/wheels/roda3_link.STL" />
      </geometry>
      <surface>
       <friction>
        <ode>
         <mu>0</mu>
         <mu2>0</mu2>
        </ode>
       </friction> 
      </surface>
    </collision>

    <inertial>
      <origin xyz="2.7756E-16 -2.0262E-15 0.017714" />
      <mass value="0.13541" />
      <inertia 
        ixx="7.4142E-05"
        ixy="1.6941E-21"
        ixz="9.0984E-19"
        iyy="7.4142E-05"
        iyz="-6.501E-18"
        izz="0.00013101" />
    </inertial>
  </link> 
  
    <joint name="roda4_joint" type="fixed">
    <parent link="caster4_link"/>
    <child link="roda4_link"/>
    <origin xyz="0 -0.0035 0" rpy="0 0 0.057049"/>
    <axis xyz="0 0 0"/>
    <dynamics damping="0" friction="0"/>
  </joint>
  
  <link name="roda4_link">
      <visual>
      <origin xyz="0 0 0" rpy="0 0 0"/>
      <geometry>
        <mesh filename="package://turtlebot3_description/meshes/wheels/roda4_link.STL" />
      </geometry>
      <material name="orange"/>
    </visual>
    
    <collision>
      <origin xyz="0 0 0" rpy="0 0 0"/>
      <geometry>
        <mesh filename="package://turtlebot3_description/meshes/wheels/roda4_link.STL" />
      </geometry>
      <surface>
       <friction>
        <ode>
         <mu>0</mu>
         <mu2>0</mu2>
        </ode>
       </friction> 
      </surface>
    </collision>

    <inertial>
      <origin xyz="2.7756E-16 -2.1164E-15 0.017714" />
      <mass value="0.13541" />
      <inertia 
        ixx="7.4142E-05"
        ixy="1.6941E-21"
        ixz="9.1444E-19"
        iyy="7.4142E-05"
        iyz="-6.7819E-18"
        izz="0.00013101" />
    </inertial>
  </link> 
</robot>
